Workbook
Name mot_exibicao_de_escala: Tabela1[[#All],[MOTORISTA + MATRICULA]]
Name mot_exibicao_de_escala: Tabela1[[#All],[MOTORISTA + MATRICULA]]
Name mot_exibicao_de_escala: Tabela1[[#All],[MOTORISTA + MATRICULA]]
Name mot_matricula: 'BANCO DE DADOS'!$B$1:$B$498
Name mot_nome: Tabela1[[#All],[MOTORISTA]]
Name mot_nome: Tabela1[[#All],[MOTORISTA]]
Name mot_nome: Tabela1[[#All],[MOTORISTA]]
Name prev_locais: #REF!

Sheet PAINEL
B3: =_xlfn.CONCAT("OLÁ ", 'BANCO DE DADOS'!I7,"!") -> OLÁ GUSTAVO!
B5: HOJE ESTÁ TRANQUILO
B7: > ACESSAR ESCALA DE HOJE
B8: > ATUALIZAR ESCALA DE HOJE
B9: > ACESSAR LIFEWEB
B10: > IMPRIMIR BAFÔMETROS
B12: > CARROS RESERVA: | E12: =(COUNTIF('RESERVAS E QUARTOS'!C5:C9,"PNEU")) -> 2
B13: > NASCENDO NA GARAGEM: | E13: =COUNTIF('FROTA NOTURNA'!K3:K7,"NASCE NA GARAGEM") -> 0

Sheet BOAS-VINDAS
G1: BEM VINDO AO SISTEMA DE GERENCIAMENTO AUXILIAR DE TRÁFEGO
G2: SISGET (PROJETO TRAFEG.AI)
F7: objetivo
F8: projetar uma aplicação intutitiva e técnica para uso dos assistentes de tráfego para tarefas operacionais
F10: fase atual
F11: projetando, estudando e analisando banco de dados relacional em excel
F13: próxima fase
F14: projetar interfaces de planejamento estratégico, integradas (de alguma forma) ao rastreamento e informações de trânsito
F16: desafio
F17: construir (windows - mobile) aplicação independente tendo como base este projeto para elevar segurança, desempenho e portabilidade
F19: prazo
F20: máximo: 1 ano e meio
G25: PROJETADO E DESENVOLVIDO POR GUSTAVO MELO
E26: nenhum dado sensível é coletado da Empresa Satélite Norte durante o desenvolvimento dessa aplicação
D27: os dados dísponíveis como placas, numeros de frotas, nomes e matrículas estão salvas localmente neste computador
E28: não sendo de propriedade e nem parte da aplicação como todo. | S28: x

Sheet RESERVAS E QUARTOS
B3: OFICINA | G3: =_xlfn.CONCAT("atualizado em: ",TEXT(NOW(),"DD/MM/AA - HH:MM")," (",'BANCO DE DADOS'!I7,")") -> atualizado em: 20/03/26 - 05:36 (GUSTAVO) | K3: o
B4: CÓD | C4: TIPO | D4: STATUS | E4: DESCRIÇÃO
B5: 19001 | C5: CARRO | D5: DISPONÍVEL | E5: CARRO PRONTO | G5: ALOJAMENTOS
B6: 19002 | C6: CARRO | D6: INDISPONÍVEL | E6: CARRO EM MANUTENÇÃO, FALTA TESTE | G6: QUARTO | H6: STATUS | I6: DUPLA(S) | J6: ESCALA(S) | K6: OBSERVAÇÕES
B7: 19003 | C7: CARRO | D7: DISPONÍVEL | E7: CARRO PRONTO | G7: 1 | H7: INDISPONÍVEL | I7: - | J7: - | K7: QUARTO SEM A/C
B8: SN 10001 | C8: PNEU | D8: DISPONÍVEL | E8: PNEU PRIMEIRA VIDA | G8: 2 | H8: OCUPADO | I8: ADAIL, RAMIRO, MARCIO, ROBERTO | J8: 09:30 E 11:30 | K8: -
B9: SN 10002 | C9: PNEU | D9: INDISPONÍVEL | E9: PNEU RECAPADO | G9: 3 | H9: DISPONÍVEL | I9: - | J9: - | K9: -
G10: 4 | H10: DISPONÍVEL | I10: - | J10: - | K10: -
G11: 5 | H11: DISPONÍVEL | I11: - | J11: - | K11: -
G12: 6 | H12: DISPONÍVEL | I12: - | J12: - | K12: -
G13: 7 | H13: DISPONÍVEL | I13: - | J13: - | K13: -
G14: 8 | H14: DISPONÍVEL | I14: - | J14: - | K14: -
G15: 9 | H15: DISPONÍVEL | I15: - | J15: - | K15: -
G16: 10 | H16: DISPONÍVEL | I16: - | J16: - | K16: -

Sheet POS. FROTA
D2: POSICIONAMENTO FROTA | N2: POSICIONAMENTO FROTA | X2: POSICIONAMENTO FROTA
D3: DATA | E3: FROTA | F3: HORÁRIO | G3: ORIGEM | H3: DESTINO | N3: DATA | O3: FROTA | P3: HORÁRIO | Q3: ORIGEM | R3: DESTINO | X3: DATA | Y3: FROTA | Z3: HORÁRIO | AA3: ORIGEM | AB3: DESTINO
D4: =TODAY() -> 46101 | E4: ='ESCALA DO FLUXO'!D2 -> 25007 | F4: 0.3 | G4: BELEM (PA) | H4: GOIANIA (GO) | N4: =D4 -> 46101 | O4: ='ESCALA DO FLUXO'!D7 -> 19021 | P4: 0.39583333 | Q4: GOIANIA (GO) | R4: BELEM (PA) | X4: =D4 -> 46101 | Y4: ='ESCALA DO FLUXO'!D16 -> 19024 | Z4: 0.47013889 | AA4: GOIANIA (GO) | AB4: SAO LUIS (MA)
D5: =D4 -> 46101 | E5: ='ESCALA DO FLUXO'!D3 -> 25011 | F5: 0.33333333 | G5: SAO LUIS (MA) | H5: GOIANIA (GO) | N5: =N4 -> 46101 | O5: ='ESCALA DO FLUXO'!D15 -> 25012 | P5: 0.82777778 | Q5: GOIANIA (GO) | R5: BELEM (PA) | X5: =X4 -> 46101 | Y5: ='ESCALA DO FLUXO'!D17 -> 18016 | Z5: 0.8125 | AA5: IMPERATRIZ (MA) | AB5: SAO LUIS (MA)
D6: =D10 -> 46101 | E6: ='ESCALA DO FLUXO'!D4 -> 19005 | F6: 0.39583333 | G6: SINOP (MT) | H6: FORTALEZA (CE) | N6: =N5 -> 46101 | O6: ='ESCALA DO FLUXO'!D9 -> 19010 | P6: 0.35416667 | Q6: BELEM (PA) | R6: GOIANIA (GO) | X6: =X5 -> 46101 | Y6: ='ESCALA DO FLUXO'!D18 -> 25008 | Z6: 0.84375 | AA6: GOIANIA (GO) | AB6: SAO LUIS (MA)
D7: =D5 -> 46101 | E7: ='ESCALA DO FLUXO'!D6 -> 19007 | F7: 0.39583333 | G7: TERESINA (PI) | H7: GOIANIA (GO) | N7: =N6 -> 46101 | O7: ='ESCALA DO FLUXO'!D14 -> 24014 | P7: 0.79166667 | Q7: BELEM (PA) | R7: GOIANIA (GO) | X7: =X6 -> 46101 | Y7: ='ESCALA DO FLUXO'!D10 -> 20015 | Z7: 0.29166667 | AA7: SAO LUIS (MA) | AB7: GOIANIA (GO)
D8: =D7 -> 46101 | E8: ='ESCALA DO FLUXO'!D20 -> CANCELADO | F8: 0.84166667 | G8: SAO LUIS (MA) | H8: GOIANIA (GO) | N8: =N7 -> 46101 | X8: =X7 -> 46101 | Y8: ='ESCALA DO FLUXO'!D11 -> 25005 | Z8: 0.79166667 | AA8: SAO LUIS (MA) | AB8: GOIANIA (GO)
D9: =D8 -> 46101 | E9: ='ESCALA DO FLUXO'!D21 -> 19014 | F9: 0.85416667 | G9: FORTALEZA (CE) | H9: SINOP (MT) | N9: =N8 -> 46101 | X9: =X8 -> 46101 | Y9: ='ESCALA DO FLUXO'!D12 -> CANCELADO | Z9: 0.79513889 | AA9: SAO LUIS (MA) | AB9: IMPERATRIZ (MA)
D10: =D9 -> 46101 | E10: ='ESCALA DO FLUXO'!D22 -> 19010 | F10: 0.87847222 | G10: BELEM (PA) | H10: GOIANIA (GO) | N10: =N9 -> 46101 | X10: =X9 -> 46101
D11: =D10 -> 46101 | E11: ='ESCALA DO FLUXO'!D19 -> 19015 | F11: 0.79166667 | G11: GOIANIA (GO) | H11: TERESINA (PI) | N11: =N10 -> 46101 | X11: =X10 -> 46101
D12: =D11 -> 46101 | E12: ='ESCALA RODOVIÁRIA'!G57 -> CANCELADO | F12: ='ESCALA RODOVIÁRIA'!C57 -> 0.41666667 | G12: IMPERATRIZ (MA) | H12: VILA RICA (MT) | N12: =N11 -> 46101 | X12: =X11 -> 46101
D13: POSICIONAMENTO BASE IMPERATIZ | N13: POSICIONAMENTO BASE BELÉM | X13: POSICIONAMENTO BASE SÃO LUIS
D14: CARRO RESERVA | F14: 19002 | G14: 19021 | N14: CARRO RESERVA | X14: CARRO RESERVA
D15: GRADE FUTURA | N15: GRADE FUTURA | P15: 19013 - 15/08 - 08:30 | X15: GRADE FUTURA | Z15: 19014 - 15/08 - 07:00
D16: INDISPONIVEL | F16: 20020 - motor | G16: 19016 - cx. Cambio | N16: INDISPONIVEL | P16: 19017 - manutenção | X16: INDISPONIVEL
D17: FRETAMENTO EM ANDAMENTO | N17: FRETAMENTO EM ANDAMENTO | X17: FRETAMENTO EM ANDAMENTO
D18: DATA | E18: FROTA | F18: HORARIO | G18: ORIGEM | H18: DESTINO | I18: DATA FINAL | J18: OBS | N18: DATA | O18: FROTA | P18: HORARIO | Q18: ORIGEM | R18: DESTINO | S18: DATA FINAL | U18: OBS | X18: DATA | Y18: FROTA | Z18: HORARIO | AA18: ORIGEM | AB18: DESTINO | AC18: DATA FINAL | AE18: OBS
I19: 45488 | X19: 45819 | Y19: 19016 | Z19: - | AA19: SAO LUIS (MA) | AB19: BARREIRINHAS (MA)
D21: Ultima atualização: | H21: =NOW() -> 46101.234 | N21: Ultima atualização: | R21: =NOW() -> 46101.234 | X21: Ultima atualização: | AB21: =NOW() -> 46101.234
L23: XXXXX | M23: XXXXX | V23: XXXXX | W23: XXXXX | AF23: XXXXX | AG23: XXXXX

Sheet ESCALA RODOVIÁRIA
B2: =CONCATENATE("ESCALA DE TRÁFEGO DIÁRIA - ",UPPER(TEXT('ESCALA DO FLUXO'!B2,"Dddd, DD/MM/AAAA"))) -> ESCALA DE TRÁFEGO DIÁRIA - SEXTA-FEIRA, 20/03/2026
B3: IMPERATRIZ-MA / GOIANIA-GO
B4: SERVIÇO | C4: HORÁRIO | D4: TRIPULAÇÃO | F4: TRECHO | G4: CARRO | H4: LINHA
B5: 993 | C5: 0.25 | D5: CANCELADO | E5: CANCELADO | G5: CANCELADO | H5: BEL X GYN
B6: 2014 | C6: ='ESCALA DO FLUXO'!F2 -> 0.3 | D6: =TRIM('ESCALA DO FLUXO'!I2) -> CLODOALDO PEREIRA DE LIMA - 4067 | E6: =TRIM('ESCALA DO FLUXO'!J2) -> ( MOTORISTA DE GOIÂNIA ) | F6: IMP X GYN | G6: ='ESCALA DO FLUXO'!D2 -> 25007 | H6: BEL X GYN
B7: 1072 | C7: ='ESCALA DO FLUXO'!F3 -> 0.33333333 | D7: =TRIM('ESCALA DO FLUXO'!I3) -> MARCOS ATAIDE SILVA - 1352 | E7: =TRIM('ESCALA DO FLUXO'!J3) -> FABIO MOREIRA DOS SANTOS - 3073 | F7: IMP X GYN | G7: ='ESCALA DO FLUXO'!D3 -> 25011 | H7: SLZ X GYN
B8: =IF(TEXT('ESCALA DO FLUXO'!A2,"DDDD")="SEXTA",3132,4077) -> 3132 | C8: ='ESCALA DO FLUXO'!F4 -> 0.39583333 | D8: =TRIM('ESCALA DO FLUXO'!I4) -> JOSE CARLOS BEZERRA DA SILVA - 3034 | E8: =TRIM('ESCALA DO FLUXO'!J4) -> ( MOTORISTA DE GOIÂNIA ) | F8: IMP X GYN | G8: ='ESCALA DO FLUXO'!D4 -> 19005 | H8: =IF(TEXT('ESCALA DO FLUXO'!A2,"DDDD")="SEXTA","IMP X PXT","THE X GYN") -> IMP X PXT
B9: 4075 | C9: 0.91666667 | D9: RONALDO ADRIANO COSTA SANTOS - 5637 | F9: BRC X EST | G9: ='ESCALA DO FLUXO'!D13 -> 25009 | H9: THE X GYN (BC)
D10: ='ESCALA DO FLUXO'!I13 -> LUIS ANTONIO FARIAS RIBEIRO - 2789 | E10: ='ESCALA DO FLUXO'!J13 -> 0 | F10: EST X GYN
B11: 2261 | C11: ='ESCALA DO FLUXO'!F20 -> 0.84166667 | D11: =TRIM('ESCALA DO FLUXO'!I20) -> CANCELADO | E11: =TRIM('ESCALA DO FLUXO'!J20) -> CANCELADO | F11: IMP X GYN | G11: ='ESCALA DO FLUXO'!D20 -> CANCELADO | H11: SLZ X GYN
B12: 1124 | C12: ='ESCALA DO FLUXO'!F21 -> 0.85416667 | D12: =TRIM('ESCALA DO FLUXO'!I21) -> KLEBER OLIVEIRA LIMA - 5849 | E12: =TRIM('ESCALA DO FLUXO'!J21) | F12: IMP X GYN | G12: ='ESCALA DO FLUXO'!D21 -> 19014 | H12: FOT X SIN
B13: 2103 | C13: ='ESCALA DO FLUXO'!F22 -> 0.87847222 | D13: =TRIM('ESCALA DO FLUXO'!I22) -> MARCIO DE SOUSA MATOS - 5264 | E13: =TRIM('ESCALA DO FLUXO'!J22) -> ANDSON WAGNER NASCIMENTO SOUZA - 2902 | F13: IMP X GYN | G13: ='ESCALA DO FLUXO'!D22 -> 19010 | H13: BEL X GYN
B14: ESCALA DE TRÁFEGO
B15: IMPERATRIZ-MA / TERESINA-PI
B16: SERVIÇO | C16: HORÁRIO | D16: TRIPULAÇÃO | F16: TRECHO | G16: CARRO | H16: LINHA
B17: 1125 | C17: 0.39513889 | D17: =TRIM('ESCALA DO FLUXO'!I6) -> EDUARDO SANTOS BEZERRA - 4066 | F17: IMP X STI | G17: ='ESCALA DO FLUXO'!D6 -> 19007 | H17: SIN X FOT
C18: 0.72569444 | D18: =TRIM('ESCALA DO FLUXO'!J6) | F18: STI X THE
B19: 4074 | C19: 0.29166667 | D19: ='ESCALA DO FLUXO'!I8 -> MANOEL MESSIAS SILVA DOS SANTOS - 1833 | F19: EST X BRC | G19: ='ESCALA DO FLUXO'!D8 -> 25005 | H19: GYN X THE (BC)
C20: 0.625 | D20: ='ESCALA DO FLUXO'!J8 -> 0 | F20: BRC X THE
B21: =IF(TEXT('ESCALA DO FLUXO'!A2,"DDDD")="SEXTA",9064,4076) -> 9064 | C21: 0.79861111 | D21: ='ESCALA DO FLUXO'!I19 -> FRANCISCO ALVES DA PAZ JUNIOR - 1247 | F21: IMP X STI | G21: ='ESCALA DO FLUXO'!D19 -> 19015 | H21: =IF(TEXT('ESCALA DO FLUXO'!A2,"DDDD")="SEXTA","IMP X THE","GYN X THE") -> IMP X THE
C22: 03:00 | D22: ='ESCALA DO FLUXO'!J19 -> 0 | F22: STI X THE
B23: 9064 | C23: 0.83333333 | D23: CANCELADO | E23: CANCELADO | G23: CANCELADO | H23: IMP X THE
B24: ESCALA DE TRÁFEGO
B25: IMPERATRIZ-MA / BELEM-PA
B26: SERVIÇO | C26: HORÁRIO | D26: TRIPULAÇÃO | F26: TRECHO | G26: CARRO | H26: LINHA
B27: 2100 | C27: 0.38541667 | D27: =TRIM('ESCALA DO FLUXO'!I7) -> FERNANDO ALVES DE SOUZA - 6350 | E27: =TRIM('ESCALA DO FLUXO'!J7) -> AELSON PEREIRA DO NASCIMENTO - 5682 | F27: IMP X BEL | G27: ='ESCALA DO FLUXO'!D7 -> 19021 | H27: GYN X BEL
B28: 992 | C28: 0.74305556 | D28: CANCELADO | E28: CANCELADO | G28: CANCELADO | H28: GYN X BEL
B29: 2013 | C29: 0.82777778 | D29: =TRIM('ESCALA DO FLUXO'!I15) -> BRUNO MATOS DA ROCHA - 6013 | E29: =TRIM('ESCALA DO FLUXO'!J15) -> ANTONIO FRANCINALDO DE OLIVEIRA MARQUES - 5018 | F29: IMP X BEL | G29: ='ESCALA DO FLUXO'!D15 -> 25012 | H29: GYN X BEL
B30: ESCALA DE TRÁFEGO
B31: BELÉM-PA / IMPERATRIZ-MA
B32: SERVIÇO | C32: HORÁRIO | D32: TRIPULAÇÃO | F32: TRECHO | G32: CARRO | H32: LINHA
B33: 2103 | C33: 0.375 | D33: =TRIM('ESCALA DO FLUXO'!I9) -> ANTONIO MARQUES NETO DOS SANTOS - 1738 | E33: =TRIM('ESCALA DO FLUXO'!J9) -> JERZUALDO DA SILVA GOMES - 4077 | F33: BEL X IMP | G33: ='ESCALA DO FLUXO'!D9 -> 19010 | H33: BEL X GYN
B34: 993 | C34: 0.77083333 | D34: CANCELADO | E34: CANCELADO | G34: CANCELADO | H34: BEL X GYN
B35: 2014 | C35: ='ESCALA DO FLUXO'!F14 -> 0.77083333 | D35: =TRIM('ESCALA DO FLUXO'!I14) -> JAKTAN DE OLIVEIRA RODRIGUES - 5836 | E35: =TRIM('ESCALA DO FLUXO'!J14) -> ARIANO SILVA OLIVEIRA - 6349 | F35: BEL X IMP | G35: ='ESCALA DO FLUXO'!D14 -> 24014 | H35: BEL X GYN
B36: ESCALA DE TRÁFEGO
B37: IMPERATRIZ-MA / SÃO LUIS-MA
B38: SERVIÇO | C38: HORÁRIO | D38: TRIPULAÇÃO | F38: TRECHO | G38: CARRO | H38: LINHA
B39: 2260 | C39: 0.47013889 | D39: =TRIM('ESCALA DO FLUXO'!I16) -> FRANCISCO BATISTA DE LIMA - 1827 | F39: IMP X STI | G39: ='ESCALA DO FLUXO'!D16 -> 19024 | H39: GYN X SLZ
D40: =TRIM('ESCALA DO FLUXO'!J16) -> EDIVALDO DE ARAUJO - 6217 | F40: STI X SLZ
B41: 4098 | C41: 0.8125 | D41: =TRIM('ESCALA DO FLUXO'!I17) -> REGINALDO DE SOUSA OLIVEIRA - 5412 | F41: IMP X STI | G41: ='ESCALA DO FLUXO'!D17 -> 18016 | H41: IMP X SLZ
...

Sheet ESCALA DO FLUXO
B1: DATA | C1: GARAGEM | D1: CARRO | E1: HR. GA | F1: HR. RD | G1: ORIGEM | H1: DESTINO | I1: MOTORISTA + MATRÍCULA | J1: MOTORISTA + MATRÍCULA2 | K1: LINHA
A2: SEXTA | B2: 46101 | C2: IMPERATRIZ | D2: 25007 | E2: 0.25486111 | F2: 0.3 | G2: IMPERATRIZ (MA) | H2: GOIANIA (GO) | I2: CLODOALDO PEREIRA DE LIMA - 4067 | J2: ( MOTORISTA DE GOIÂNIA ) | K2: GOIANIA (GO) X BELEM (PA)
B3: 46101 | C3: IMPERATRIZ | D3: 25011 | E3: 0.32291667 | F3: 0.33333333 | G3: IMPERATRIZ (MA) | H3: GOIANIA (GO) | I3: MARCOS ATAIDE SILVA - 1352 | J3: FABIO MOREIRA DOS SANTOS - 3073 | K3: GOIANIA (GO) X SAO LUIS (MA)
B4: 46101 | C4: IMPERATRIZ | D4: 19005 | E4: 0.38888889 | F4: 0.39583333 | G4: IMPERATRIZ (MA) | H4: GOIANIA (GO) | I4: JOSE CARLOS BEZERRA DA SILVA - 3034 | J4: ( MOTORISTA DE GOIÂNIA ) | K4: GOIANIA (GO) X TERESINA (PI) VIA STI
B5: 46101 | C5: IMPERATRIZ | D5: CANCELADO | E5: 0.375 | F5: 0.41666667 | G5: IMPERATRIZ (MA) | H5: VILA RICA (MT) | I5: CANCELADO | J5: CANCELADO | K5: IMPERATRIZ (MA) X VILA RICA (MT)
B6: 46101 | C6: IMPERATRIZ | D6: 19007 | E6: 0.38888889 | F6: 0.37708333 | G6: IMPERATRIZ (MA) | H6: TERESINA (PI) | I6: EDUARDO SANTOS BEZERRA - 4066 | K6: FORTALEZA (CE) X SINOP (MT)
B7: 46101 | C7: IMPERATRIZ | D7: 19021 | E7: 0.38958333 | F7: 0.38541667 | G7: IMPERATRIZ (MA) | H7: BELEM (PA) | I7: FERNANDO ALVES DE SOUZA - 6350 | J7: AELSON PEREIRA DO NASCIMENTO - 5682 | K7: GOIANIA (GO) X BELEM (PA)
B8: 46101 | C8: IMPERATRIZ | D8: 25005 | E8: 0.375 | F8: 0.39930556 | G8: ARAGUAINA (TO) | H8: TERESINA (PI) | I8: MANOEL MESSIAS SILVA DOS SANTOS - 1833 | K8: GOIANIA (GO) X TERESINA (PI) VIA BC
B9: 46101 | C9: IMPERATRIZ | D9: 19010 | E9: 0.375 | F9: 0.41666667 | G9: BELEM (PA) | H9: IMPERATRIZ (MA) | I9: ANTONIO MARQUES NETO DOS SANTOS - 1738 | J9: JERZUALDO DA SILVA GOMES - 4077 | K9: GOIANIA (GO) X BELEM (PA)
B10: 46101 | C10: IMPERATRIZ | D10: 20015 | E10: 0.25 | F10: 0.29166667 | G10: SAO LUIS (MA) | H10: IMPERATRIZ (MA) | I10: CARLOS ADRIANO DE SOUZA DO NASCIMENTO - 6222 | J10: LEANDRO DE OLIVEIRA MELO - 2151 | K10: GOIANIA (GO) X SAO LUIS (MA)
B11: 46101 | C11: IMPERATRIZ | D11: 25005 | E11: 0.75 | F11: 0.79166667 | G11: SAO LUIS (MA) | H11: IMPERATRIZ (MA) | I11: KAYLSON KLEYTON DA SILVA COSTA - 6224 | J11: JARDEL DE SOUSA OLIVEIRA - 5992 | K11: GOIANIA (GO) X SAO LUIS (MA)
B12: 46101 | C12: IMPERATRIZ | D12: CANCELADO | E12: 0.77083333 | F12: 0.79513889 | G12: SAO LUIS (MA) | H12: IMPERATRIZ (MA) | I12: CANCELADO | J12: CANCELADO | K12: IMPERATRIZ (MA) X SÃO LUIS (MA)
B13: 46101 | C13: IMPERATRIZ | D13: 25009 | E13: 0.89583333 | F13: 0.91666667 | G13: ARAGUAINA (TO) | H13: GOIANIA (GO) | I13: LUIS ANTONIO FARIAS RIBEIRO - 2789 | K13: GOIANIA (GO) X TERESINA (PI) VIA BC
B14: 46101 | C14: IMPERATRIZ | D14: 24014 | E14: 0.76041667 | F14: 0.77083333 | G14: BELEM (PA) | H14: IMPERATRIZ (MA) | I14: JAKTAN DE OLIVEIRA RODRIGUES - 5836 | J14: ARIANO SILVA OLIVEIRA - 6349 | K14: GOIANIA (GO) X BELEM (PA)
B15: 46101 | C15: IMPERATRIZ | D15: 25012 | E15: 0.76041667 | F15: 0.82777778 | G15: IMPERATRIZ (MA) | H15: BELEM (PA) | I15: BRUNO MATOS DA ROCHA - 6013 | J15: ANTONIO FRANCINALDO DE OLIVEIRA MARQUES - 5018 | K15: GOIANIA (GO) X BELEM (PA)
B16: 46101 | C16: IMPERATRIZ | D16: 19024 | E16: 0.40763889 | F16: 0.47013889 | G16: IMPERATRIZ (MA) | H16: SAO LUIS (MA) | I16: FRANCISCO BATISTA DE LIMA - 1827 | J16: EDIVALDO DE ARAUJO - 6217 | K16: GOIANIA (GO) X SAO LUIS (MA)
B17: 46101 | C17: IMPERATRIZ | D17: 18016 | E17: 0.77083333 | F17: 0.8125 | G17: IMPERATRIZ (MA) | H17: SAO LUIS (MA) | I17: REGINALDO DE SOUSA OLIVEIRA - 5412 | J17: JOSE ANTONIO OLIVEIRA SILVA NETO - 6378 | K17: IMPERATRIZ (MA) X SÃO LUIS (MA)
B18: 46101 | C18: IMPERATRIZ | D18: 25008 | E18: 0.8125 | F18: 0.84375 | G18: IMPERATRIZ (MA) | H18: SAO LUIS (MA) | I18: JARDEL DE SOUSA OLIVEIRA - 5992 | J18: KAYLSON KLEYTON DA SILVA COSTA - 6224 | K18: GOIANIA (GO) X SAO LUIS (MA)
B19: 46101 | C19: IMPERATRIZ | D19: 19015 | E19: 0.77083333 | F19: 0.79861111 | G19: IMPERATRIZ (MA) | H19: TERESINA (PI) | I19: FRANCISCO ALVES DA PAZ JUNIOR - 1247 | K19: GOIANIA (GO) X TERESINA (PI) VIA STI
B20: 46101 | C20: IMPERATRIZ | D20: CANCELADO | E20: 0.8125 | F20: 0.84166667 | G20: IMPERATRIZ (MA) | H20: GOIANIA (GO) | I20: CANCELADO | J20: CANCELADO | K20: GOIANIA (GO) X SAO LUIS (MA)
B21: 46101 | C21: IMPERATRIZ | D21: 19014 | E21: 0.8125 | F21: 0.85416667 | G21: IMPERATRIZ (MA) | H21: GOIANIA (GO) | I21: KLEBER OLIVEIRA LIMA - 5849 | K21: FORTALEZA (CE) X SINOP (MT)
B22: 46101 | C22: IMPERATRIZ | D22: 19010 | E22: 0.84722222 | F22: 0.87847222 | G22: IMPERATRIZ (MA) | H22: GOIANIA (GO) | I22: MARCIO DE SOUSA MATOS - 5264 | J22: ANDSON WAGNER NASCIMENTO SOUZA - 2902 | K22: GOIANIA (GO) X BELEM (PA)
A28: SEGUNDA | B28: 45873 | C28: IMPERATRIZ | D28: 25008 | E28: 0.25486111 | F28: 0.3 | G28: IMPERATRIZ (MA) | H28: GOIANIA (GO) | I28: JOSE ATAZ QUINTINO - 6048 | J28: WOLNEY EDUARDO DE OLIVEIRA - 5607 | K28: GOIANIA (GO) X BELEM (PA)
B29: 45873 | C29: IMPERATRIZ | D29: 24011 | E29: 0.32291667 | F29: 0.33333333 | G29: IMPERATRIZ (MA) | H29: GOIANIA (GO) | I29: JOAO BATISTA DA SILVA - 1410 | J29: WILLIAN DE SOUZA BANDEIRA- 2025 | K29: GOIANIA (GO) X SAO LUIS (MA)
B30: 45873 | C30: IMPERATRIZ | D30: 15600 | E30: 0.38888889 | F30: 0.39583333 | G30: IMPERATRIZ (MA) | H30: GOIANIA (GO) | I30: EURIPEDES BARSANULFO DIAS ROSA- 1951 | J30: NEIRIVAL MOREIRA PINTO- 5432 | K30: GOIANIA (GO) X TERESINA (PI) VIA STI
B31: 45873 | C31: IMPERATRIZ | D31: CANCELADO | E31: 0.375 | F31: 0.41666667 | G31: IMPERATRIZ (MA) | H31: VILA RICA (MT) | I31: CANCELADO | J31: CANCELADO | K31: GOIANIA (GO) X VILA RICA (MT)
B32: 45873 | C32: IMPERATRIZ | D32: 17600 | E32: 0.38888889 | F32: 0.37708333 | G32: IMPERATRIZ (MA) | H32: TERESINA (PI) | I32: VALDEY OLIVEIRA ARAUJO - 2790 | J32: FRANCISCO DAS CHAGAS DOS SANTOS ANGELO - 5299 | K32: FORTALEZA (CE) X SINOP (MT)
B33: 45873 | C33: IMPERATRIZ | D33: 20022 | E33: 0.38958333 | F33: 0.38541667 | G33: IMPERATRIZ (MA) | H33: BELEM (PA) | I33: ADEMILTON DE OLIVEIRA SILVA - 5559 | J33: MARCIO RODRIGUES DA COSTA - 5993 | K33: GOIANIA (GO) X BELEM (PA)
B34: 45873 | C34: IMPERATRIZ | D34: 24006 | E34: 0.375 | F34: 0.39930556 | G34: ARAGUAINA (TO) | H34: TERESINA (PI) | I34: JWEBISON DE BRITO SOUZA - 2999 | J34: WASHINGTON ALVES BRITO - 1553 | K34: GOIANIA (GO) X TERESINA (PI) VIA BC
B35: 45873 | C35: IMPERATRIZ | D35: 19022 | E35: 0.375 | F35: 0.41666667 | G35: BELEM (PA) | H35: IMPERATRIZ (MA) | I35: LUIZ CARLOS MARIANO SIQUEIRA - 5634 | J35: AELSON PEREIRA DO NASCIMENTO - 5682 | K35: GOIANIA (GO) X BELEM (PA)
B36: 45873 | C36: IMPERATRIZ | D36: 19012 | E36: 0.25 | F36: 0.29166667 | G36: SAO LUIS (MA) | H36: IMPERATRIZ (MA) | I36: LAUCEANDO DA SILVA ROCHA - 6220 | J36: FABIO MOREIRA DOS SANTOS - 3073 | K36: GOIANIA (GO) X SAO LUIS (MA)
B37: 45873 | C37: IMPERATRIZ | D37: 24003 | E37: 0.75 | F37: 0.79166667 | G37: SAO LUIS (MA) | H37: IMPERATRIZ (MA) | I37: RAIMUNDO COSTA SILVA - 6226 | J37: JEFFERSON CARDOSO DOS SANTOS - 5837 | K37: GOIANIA (GO) X SAO LUIS (MA)
B38: 45873 | C38: IMPERATRIZ | D38: CANCELADO | E38: 0.77083333 | F38: 0.79513889 | G38: SAO LUIS (MA) | H38: IMPERATRIZ (MA) | I38: CANCELADO | J38: CANCELADO | K38: IMPERATRIZ (MA) X SÃO LUIS (MA)
B39: 45873 | C39: IMPERATRIZ | D39: 24015 | E39: 0.89583333 | F39: 0.91666667 | G39: ARAGUAINA (TO) | H39: GOIANIA (GO) | I39: JOSE ANTONIO INACIO VIEIRA - 5279 | J39: MARCELO RIZO SANTANA - 2048 | K39: GOIANIA (GO) X TERESINA (PI) VIA BC
B40: 45873 | C40: IMPERATRIZ | D40: 24002 | E40: 0.76041667 | F40: 0.77083333 | G40: BELEM (PA) | H40: IMPERATRIZ (MA) | I40: ANTONIO RAMIRO WEBER - 5452 | J40: JOSE ALVES DA ROCHA - 5035 | K40: GOIANIA (GO) X BELEM (PA)
B41: 45873 | C41: IMPERATRIZ | D41: 24013 | E41: 0.76041667 | F41: 0.82777778 | G41: IMPERATRIZ (MA) | H41: BELEM (PA) | I41: MANOEL MESSIAS SILVA DOS SANTOS - 1833 | J41: JOAO FERREIRA COSTA - 5545 | K41: GOIANIA (GO) X BELEM (PA)
B42: 45873 | C42: IMPERATRIZ | D42: 19019 | E42: 0.40763889 | F42: 0.47013889 | G42: IMPERATRIZ (MA) | H42: SAO LUIS (MA) | I42: BRUNO MATOS DA ROCHA - 6013 | J42: PAULO ENEAS FARIAS ARAUJO - 6218 | K42: GOIANIA (GO) X SAO LUIS (MA)
B43: 45873 | C43: IMPERATRIZ | D43: CANCELADO | E43: 0.77083333 | F43: 0.8125 | G43: IMPERATRIZ (MA) | H43: SAO LUIS (MA) | I43: CANCELADO | J43: CANCELADO | K43: IMPERATRIZ (MA) X SÃO LUIS (MA)
B44: 45873 | C44: IMPERATRIZ | D44: 25007 | E44: 0.8125 | F44: 0.84375 | G44: IMPERATRIZ (MA) | H44: SAO LUIS (MA) | I44: EDUARDO SANTOS BEZERRA - 4066 | J44: EDIVALDO DE ARAUJO - 6214 | K44: GOIANIA (GO) X SAO LUIS (MA)
B45: 45873 | C45: IMPERATRIZ | D45: 20013 | E45: 0.77083333 | F45: 0.79861111 | G45: IMPERATRIZ (MA) | H45: TERESINA (PI) | I45: RONNE RODRIGUES DE SOUSA - 5025 | J45: RICARDO AUGUSTO TEIXEIRA SANTOS - 5660 | K45: GOIANIA (GO) X TERESINA (PI) VIA STI
...

Sheet FROTA DIURNA
A1: DATA | B1: SERV | C1: SAIDA | D1: FROTA | E1: PLACA | F1: MOTORISTA A | G1: MAT A | H1: MOTORISTA B | I1: MAT B | J1: LINHA
A2: =escala_do_fluxo[[#This Row],[DATA]] -> 46101 | B2: ='ESCALA RODOVIÁRIA'!B6 -> 2014 | C2: ='ESCALA RODOVIÁRIA'!C6 -> 0.3 | D2: ='ESCALA RODOVIÁRIA'!G6 -> 25007 | E2: {=_xlfn.XLOOKUP(D2,Tabela6[[#All],[Veículo]],Tabela6[[#All],[Placa]],"N/E",1,1)} -> OGT8A57 | F2: =IFERROR(TRIM(_xlfn.TEXTBEFORE('ESCALA RODOVIÁRIA'!D6,"-")),"CANCELADO") -> CLODOALDO PEREIRA DE LIMA | G2: =TRIM(_xlfn.TEXTAFTER('ESCALA RODOVIÁRIA'!D6,"-")) -> 4067 | H2: =IFERROR(TRIM(_xlfn.TEXTBEFORE('ESCALA RODOVIÁRIA'!E6, "-")),"CANCELADO") -> CANCELADO | I2: =TRIM(_xlfn.TEXTAFTER('ESCALA RODOVIÁRIA'!E6,"-")) -> #N/A | J2: =_xlfn.CONCAT('ESCALA RODOVIÁRIA'!H6, " ",TEXT(C2,"HH:MM")) -> BEL X GYN 07:12
A3: =A2 -> 46101 | B3: ='ESCALA RODOVIÁRIA'!B7 -> 1072 | C3: ='ESCALA RODOVIÁRIA'!C7 -> 0.33333333 | D3: ='ESCALA RODOVIÁRIA'!G7 -> 25011 | E3: {=_xlfn.XLOOKUP(D3,Tabela6[[#All],[Veículo]],Tabela6[[#All],[Placa]],"N/E",1,1)} -> OGT8A57 | F3: =IFERROR(TRIM(_xlfn.TEXTBEFORE('ESCALA RODOVIÁRIA'!D7,"-")),"CANCELADO") -> MARCOS ATAIDE SILVA | G3: =TRIM(_xlfn.TEXTAFTER('ESCALA RODOVIÁRIA'!D7,"-")) -> 1352 | H3: =IFERROR(TRIM(_xlfn.TEXTBEFORE('ESCALA RODOVIÁRIA'!E7, "-")),"CANCELADO") -> FABIO MOREIRA DOS SANTOS | I3: =TRIM(_xlfn.TEXTAFTER('ESCALA RODOVIÁRIA'!E7,"-")) -> 3073 | J3: =_xlfn.CONCAT('ESCALA RODOVIÁRIA'!H7, " ",TEXT(C3,"HH:MM")) -> SLZ X GYN 08:00
A4: =A7 -> 46101 | B4: ='ESCALA RODOVIÁRIA'!B8 -> 3132 | C4: ='ESCALA RODOVIÁRIA'!C8 -> 0.39583333 | D4: ='ESCALA RODOVIÁRIA'!G8 -> 19005 | E4: {=_xlfn.XLOOKUP(D4,Tabela6[[#All],[Veículo]],Tabela6[[#All],[Placa]],"N/E",1,1)} -> QTQ4724 | F4: =IFERROR(TRIM(_xlfn.TEXTBEFORE('ESCALA RODOVIÁRIA'!D8,"-")),"CANCELADO") -> JOSE CARLOS BEZERRA DA SILVA | G4: =TRIM(_xlfn.TEXTAFTER('ESCALA RODOVIÁRIA'!D8,"-")) -> 3034 | H4: =IFERROR(TRIM(_xlfn.TEXTBEFORE('ESCALA RODOVIÁRIA'!E8, "-")),"CANCELADO") -> CANCELADO | I4: =TRIM(_xlfn.TEXTAFTER('ESCALA RODOVIÁRIA'!E8,"-")) -> #N/A | J4: =_xlfn.CONCAT('ESCALA RODOVIÁRIA'!H8, " ",TEXT(C4,"HH:MM")) -> IMP X PXT 09:30
A5: =A8 -> 46101 | B5: ='ESCALA RODOVIÁRIA'!B57 -> 9080 | C5: ='ESCALA RODOVIÁRIA'!C57 -> 0.41666667 | D5: ='ESCALA RODOVIÁRIA'!G57 -> CANCELADO | E5: {=_xlfn.XLOOKUP(D5,Tabela6[[#All],[Veículo]],Tabela6[[#All],[Placa]],"N/E",1,1)} -> SDC3B39 | F5: =IFERROR(TRIM(_xlfn.TEXTBEFORE('ESCALA RODOVIÁRIA'!D57, "-")),"CANCELADO") -> CANCELADO | G5: =IFERROR(TRIM(_xlfn.TEXTAFTER('ESCALA RODOVIÁRIA'!D57,"-")),"N/A") -> N/A | H5: =IFERROR(TRIM(_xlfn.TEXTBEFORE('ESCALA RODOVIÁRIA'!E57, "-")),"CANCELADO") -> CANCELADO | I5: =IFERROR(TRIM(_xlfn.TEXTAFTER('ESCALA RODOVIÁRIA'!E57,"-")),"N/A") -> N/A | J5: =_xlfn.CONCAT('ESCALA RODOVIÁRIA'!H57, " ",TEXT(C5,"HH:MM")) -> IMP X VLR 10:00
A6: =A3 -> 46101 | B6: ='ESCALA RODOVIÁRIA'!B17 -> 1125 | C6: ='ESCALA RODOVIÁRIA'!C17 -> 0.39513889 | D6: ='ESCALA RODOVIÁRIA'!G17 -> 19007 | E6: {=_xlfn.XLOOKUP(D6,Tabela6[[#All],[Veículo]],Tabela6[[#All],[Placa]],"N/E",1,1)} -> QTP0317 | F6: =IFERROR(TRIM(_xlfn.TEXTBEFORE('ESCALA RODOVIÁRIA'!D17,"-")),"CANCELADO") -> EDUARDO SANTOS BEZERRA | G6: =TRIM(_xlfn.TEXTAFTER('ESCALA RODOVIÁRIA'!D17,"-")) -> 4066 | H6: =IFERROR(TRIM(_xlfn.TEXTBEFORE('ESCALA RODOVIÁRIA'!D18, "-")),"CANCELADO") -> CANCELADO | I6: =TRIM(_xlfn.TEXTAFTER('ESCALA RODOVIÁRIA'!D18,"-")) -> #N/A | J6: =_xlfn.CONCAT('ESCALA RODOVIÁRIA'!H17, " ",TEXT(C6,"HH:MM")) -> SIN X FOT 09:29
A7: =A6 -> 46101 | B7: ='ESCALA RODOVIÁRIA'!B27 -> 2100 | C7: ='ESCALA RODOVIÁRIA'!C27 -> 0.38541667 | D7: ='ESCALA RODOVIÁRIA'!G27 -> 19021 | E7: {=_xlfn.XLOOKUP(D7,Tabela6[[#All],[Veículo]],Tabela6[[#All],[Placa]],"N/E",1,1)} -> QTR5657 | F7: =IFERROR(TRIM(_xlfn.TEXTBEFORE('ESCALA RODOVIÁRIA'!D27, "-")),"CANCELADO") -> FERNANDO ALVES DE SOUZA | G7: =TRIM(_xlfn.TEXTAFTER('ESCALA RODOVIÁRIA'!D27,"-")) -> 6350 | H7: =IFERROR(TRIM(_xlfn.TEXTBEFORE('ESCALA RODOVIÁRIA'!E27, "-")),"CANCELADO") -> AELSON PEREIRA DO NASCIMENTO | I7: =TRIM(_xlfn.TEXTAFTER('ESCALA RODOVIÁRIA'!E27,"-")) -> 5682 | J7: =_xlfn.CONCAT('ESCALA RODOVIÁRIA'!H27, " ",TEXT(C7,"HH:MM")) -> GYN X BEL 09:15
A8: =A4 -> 46101 | B8: ='ESCALA RODOVIÁRIA'!B39 -> 2260 | C8: ='ESCALA RODOVIÁRIA'!C39 -> 0.47013889 | D8: ='ESCALA RODOVIÁRIA'!G39 -> 19024 | E8: {=_xlfn.XLOOKUP(D8,Tabela6[[#All],[Veículo]],Tabela6[[#All],[Placa]],"N/E",1,1)} -> QTP1769 | F8: =IFERROR(TRIM(_xlfn.TEXTBEFORE('ESCALA RODOVIÁRIA'!D39, "-")),"CANCELADO") -> FRANCISCO BATISTA DE LIMA | G8: =TRIM(_xlfn.TEXTAFTER('ESCALA RODOVIÁRIA'!D39,"-")) -> 1827 | H8: =IFERROR(TRIM(_xlfn.TEXTBEFORE('ESCALA RODOVIÁRIA'!D40, "-")),"CANCELADO") -> EDIVALDO DE ARAUJO | I8: =TRIM(_xlfn.TEXTAFTER('ESCALA RODOVIÁRIA'!D40,"-")) -> 6217 | J8: =_xlfn.CONCAT('ESCALA RODOVIÁRIA'!H39, " ",TEXT(C8,"HH:MM")) -> GYN X SLZ 11:17

Sheet FROTA NOTURNA
A1: DATA | B1: HORÁRIO | C1: SERVIÇO | D1: FROTA | E1: PLACA | F1: MOTORISTA A | G1: MAT A | H1: MOTORISTA B | I1: MAT B | J1: LINHA
A2: =A3 -> 46101 | B2: ='ESCALA RODOVIÁRIA'!C41 -> 0.8125 | C2: ='ESCALA RODOVIÁRIA'!B41 -> 4098 | D2: ='ESCALA RODOVIÁRIA'!G41 -> 18016 | E2: {=IF(D2="CANCELADO","N/A",_xlfn.XLOOKUP(D2,Tabela6[[#All],[Veículo]],Tabela6[[#All],[Placa]],"N/E",1,1))} -> PRK6658 | F2: =IFERROR(TRIM(_xlfn.TEXTBEFORE('ESCALA RODOVIÁRIA'!D41,"-")),"CANCELADO") -> REGINALDO DE SOUSA OLIVEIRA | G2: =IFERROR(TRIM(_xlfn.TEXTAFTER('ESCALA RODOVIÁRIA'!D41,"-")),"N/A") -> 5412 | H2: STI | I2: - | J2: =_xlfn.CONCAT("IMP X SLZ ",TEXT(B2,"HH:MM")) -> IMP X SLZ 19:30
A3: =escala_do_fluxo[[#This Row],[DATA]] -> 46101 | B3: ='ESCALA RODOVIÁRIA'!C21 -> 0.79861111 | C3: =IF(TEXT(TODAY(),"DDDD")="SEXTA-FEIRA",9064,4076) -> 9064 | D3: ='ESCALA RODOVIÁRIA'!G21 -> 19015 | E3: {=IF(D3="CANCELADO","N/A",_xlfn.XLOOKUP(D3,Tabela6[[#All],[Veículo]],Tabela6[[#All],[Placa]],"N/E",1,1))} -> QTS1804 | F3: =IFERROR(TRIM(_xlfn.TEXTBEFORE('ESCALA RODOVIÁRIA'!D21,"-")),"CANCELADO") -> FRANCISCO ALVES DA PAZ JUNIOR | G3: =TRIM(_xlfn.TEXTAFTER('ESCALA RODOVIÁRIA'!D21,"-")) -> 1247 | H3: =IFERROR(TRIM(_xlfn.TEXTBEFORE('ESCALA RODOVIÁRIA'!F21,"-")),"CANCELADO") -> CANCELADO | I3: =TRIM(_xlfn.TEXTAFTER('ESCALA RODOVIÁRIA'!F21,"-")) -> #N/A | J3: =IF(TEXT(A3,"DDDD")="SEXTA-FEIRA","IMP X THE 19:00","GYN X THE 19:00") -> IMP X THE 19:00 | N3: CARROS RESERVA | O3: PNEUS RESERVA | P3: OCORRÊNCIAS | Q3: OUTROS
A4: =A2 -> 46101 | B4: 0.82777778 | C4: ='ESCALA RODOVIÁRIA'!B29 -> 2013 | D4: ='ESCALA RODOVIÁRIA'!G29 -> 25012 | E4: {=IF(D4="CANCELADO","N/A",_xlfn.XLOOKUP(D4,Tabela6[[#All],[Veículo]],Tabela6[[#All],[Placa]],"N/E",1,1))} -> OGT8A57 | F4: =IFERROR(TRIM(_xlfn.TEXTBEFORE('ESCALA RODOVIÁRIA'!D29,"-")),"CANCELADO") -> BRUNO MATOS DA ROCHA | G4: =TRIM(_xlfn.TEXTAFTER('ESCALA RODOVIÁRIA'!D29,"-")) -> 6013 | H4: =IFERROR(TRIM(_xlfn.TEXTBEFORE('ESCALA RODOVIÁRIA'!E29,"-")),"CANCELADO") -> ANTONIO FRANCINALDO DE OLIVEIRA MARQUES | I4: =TRIM(_xlfn.TEXTAFTER('ESCALA RODOVIÁRIA'!E29,"-")) -> 5018 | J4: =_xlfn.CONCAT("GYN X BEL ",TEXT(B4,"HH:MM")) -> GYN X BEL 19:52 | N4: 16700 | P4: N/A | Q4: N/A
A5: =A4 -> 46101 | B5: ='ESCALA RODOVIÁRIA'!C11 -> 0.84166667 | C5: 2261 | D5: ='ESCALA RODOVIÁRIA'!G11 -> CANCELADO | E5: {=IF(D5="CANCELADO","N/A",_xlfn.XLOOKUP(D5,Tabela6[[#All],[Veículo]],Tabela6[[#All],[Placa]],"N/E",1,1))} -> N/A | F5: =IFERROR(TRIM(_xlfn.TEXTBEFORE('ESCALA RODOVIÁRIA'!D11,"-")),"CANCELADO") -> CANCELADO | G5: =TRIM(_xlfn.TEXTAFTER('ESCALA RODOVIÁRIA'!D11,"-")) -> #N/A | H5: =IFERROR(TRIM(_xlfn.TEXTBEFORE('ESCALA RODOVIÁRIA'!E11,"-")),"CANCELADO") -> CANCELADO | I5: =TRIM(_xlfn.TEXTAFTER('ESCALA RODOVIÁRIA'!E11,"-")) -> #N/A | J5: =_xlfn.CONCAT("SLZ X GYN ",TEXT(B5,"HH:MM")) -> SLZ X GYN 20:12 | N5: 15900
A6: =A5 -> 46101 | B6: ='ESCALA RODOVIÁRIA'!C43 -> 0.84375 | C6: 1071 | D6: ='ESCALA RODOVIÁRIA'!G43 -> 25008 | E6: {=IF(D6="CANCELADO","N/A",_xlfn.XLOOKUP(D6,Tabela6[[#All],[Veículo]],Tabela6[[#All],[Placa]],"N/E",1,1))} -> OGT8A57 | F6: =IFERROR(TRIM(_xlfn.TEXTBEFORE('ESCALA RODOVIÁRIA'!D43,"-")),"CANCELADO") -> JARDEL DE SOUSA OLIVEIRA | G6: =TRIM(_xlfn.TEXTAFTER('ESCALA RODOVIÁRIA'!D43,"-")) -> 5992 | H6: =IFERROR(TRIM(_xlfn.TEXTBEFORE('ESCALA RODOVIÁRIA'!F43,"-")),"CANCELADO") -> CANCELADO | I6: =TRIM(_xlfn.TEXTAFTER('ESCALA RODOVIÁRIA'!F43,"-")) -> #N/A | J6: =_xlfn.CONCAT("GYN X SLZ ",TEXT(B6,"HH:MM")) -> GYN X SLZ 20:15
A7: =A6 -> 46101 | B7: ='ESCALA RODOVIÁRIA'!C12 -> 0.85416667 | C7: 1124 | D7: ='ESCALA RODOVIÁRIA'!G12 -> 19014 | E7: {=IF(D7="CANCELADO","N/A",_xlfn.XLOOKUP(D7,Tabela6[[#All],[Veículo]],Tabela6[[#All],[Placa]],"N/E",1,1))} -> QTS1814 | F7: =IFERROR(TRIM(_xlfn.TEXTBEFORE('ESCALA RODOVIÁRIA'!D12,"-")),"CANCELADO") -> KLEBER OLIVEIRA LIMA | G7: =TRIM(_xlfn.TEXTAFTER('ESCALA RODOVIÁRIA'!D12,"-")) -> 5849 | H7: =IFERROR(TRIM(_xlfn.TEXTBEFORE('ESCALA RODOVIÁRIA'!E12,"-")),"CANCELADO") -> CANCELADO | I7: =TRIM(_xlfn.TEXTAFTER('ESCALA RODOVIÁRIA'!E12,"-")) -> #N/A | J7: =_xlfn.CONCAT("FOT X SIN ",TEXT(B7,"HH:MM")) -> FOT X SIN 20:30
A8: =A7 -> 46101 | B8: ='ESCALA RODOVIÁRIA'!C13 -> 0.87847222 | C8: 2103 | D8: ='ESCALA RODOVIÁRIA'!G13 -> 19010 | E8: {=IF(D8="CANCELADO","N/A",_xlfn.XLOOKUP(D8,Tabela6[[#All],[Veículo]],Tabela6[[#All],[Placa]],"N/E",1,1))} -> QTO8077 | F8: =IFERROR(TRIM(_xlfn.TEXTBEFORE('ESCALA RODOVIÁRIA'!D13,"-")),"CANCELADO") -> MARCIO DE SOUSA MATOS | G8: =TRIM(_xlfn.TEXTAFTER('ESCALA RODOVIÁRIA'!D13,"-")) -> 5264 | H8: =IFERROR(TRIM(_xlfn.TEXTBEFORE('ESCALA RODOVIÁRIA'!E13,"-")),"CANCELADO") -> ANDSON WAGNER NASCIMENTO SOUZA | I8: =TRIM(_xlfn.TEXTAFTER('ESCALA RODOVIÁRIA'!E13,"-")) -> 2902 | J8: =_xlfn.CONCAT("BEL X GYN ",TEXT(B8,"HH:MM")) -> BEL X GYN 21:05

Sheet PREVISÕES
C3: DATA | D3: HORÁRIO | E3: SERVIÇO | F3: FROTA | G3: PLACA | H3: MOTORISTA A | I3: MAT A | J3: MOTORISTA B | K3: MAT B | L3: LINHA | M3: PREVISÃO
C4: {='FROTA NOTURNA'!A2:E8} -> 46101 | D4: 0.8125 | E4: 4098 | F4: 18016 | G4: PRK6658 | H4: ='FROTA NOTURNA'!F2 -> REGINALDO DE SOUSA OLIVEIRA | L4: {='FROTA NOTURNA'!J2:J8} -> IMP X SLZ 19:30 | M4: GARAGEM
C5: 46101 | D5: 0.79861111 | E5: 9064 | F5: 19015 | G5: QTS1804 | H5: ='FROTA NOTURNA'!F3 -> FRANCISCO ALVES DA PAZ JUNIOR | L5: IMP X THE 19:00
C6: 46101 | D6: 0.82777778 | E6: 2013 | F6: 25012 | G6: OGT8A57 | H6: ='FROTA NOTURNA'!F4 -> BRUNO MATOS DA ROCHA | J6: ='FROTA NOTURNA'!H4 -> ANTONIO FRANCINALDO DE OLIVEIRA MARQUES | L6: GYN X BEL 19:52
C7: 46101 | D7: 0.84166667 | E7: 2261 | F7: CANCELADO | G7: N/A | H7: ='FROTA NOTURNA'!F5 -> CANCELADO | J7: ='FROTA NOTURNA'!H5 -> CANCELADO | L7: SLZ X GYN 20:12
C8: 46101 | D8: 0.84375 | E8: 1071 | F8: 25008 | G8: OGT8A57 | H8: ='FROTA NOTURNA'!F6 -> JARDEL DE SOUSA OLIVEIRA | L8: GYN X SLZ 20:15
C9: 46101 | D9: 0.85416667 | E9: 1124 | F9: 19014 | G9: QTS1814 | H9: ='FROTA NOTURNA'!F7 -> KLEBER OLIVEIRA LIMA | J9: ='FROTA NOTURNA'!H7 -> CANCELADO | L9: FOT X SIN 20:30
C10: 46101 | D10: 0.87847222 | E10: 2103 | F10: 19010 | G10: QTO8077 | H10: ='FROTA NOTURNA'!F8 -> MARCIO DE SOUSA MATOS | J10: ='FROTA NOTURNA'!H8 -> ANDSON WAGNER NASCIMENTO SOUZA | L10: BEL X GYN 21:05
C11: =C10 -> 46101 | D11: ='FRT NTR BFM'!B14 -> 0.85763889 | E11: 107 | F11: ='FRT NTR BFM'!D14 -> 17000 | H11: ='FRT NTR BFM'!F13 -> CANCELADO | J11: ='FRT NTR BFM'!F14 -> CANCELADO | L11: THE X GYN 20:35 EXTRA
J14: =_xlfn.CONCAT("última atualização: ", TEXT(NOW(),"hh:mm")) -> última atualização: 05:36

Sheet FTR DIU BFM
A1: DATA | B1: HORÁRIO | C1: SERVIÇO | D1: FROTA | E1: PLACA | F1: NOME | G1: MAT | H1: LINHA
A2: =escala_do_fluxo[[#This Row],[DATA]] -> 46101 | B2: =escala_do_fluxo[[#This Row],[HR. RD]] -> 0.3 | D2: ='ESCALA DO FLUXO'!D2 -> 25007 | E2: {=IF(D2="CANCELADO","N/A",_xlfn.XLOOKUP(D2,Tabela6[[#All],[Veículo]],Tabela6[[#All],[Placa]],"N/E",1,1))} -> OGT8A57 | F2: =IFERROR(TRIM(_xlfn.TEXTBEFORE('ESCALA DO FLUXO'!I2,"-")),"CANCELADO") -> CLODOALDO PEREIRA DE LIMA | G2: =IFERROR(TRIM(_xlfn.TEXTAFTER('ESCALA DO FLUXO'!I2,"-")),"CANCELADO") -> 4067 | H2: =_xlfn.CONCAT('ESCALA DO FLUXO'!K2, " ",TEXT('ESCALA DO FLUXO'!F2,"HH:MM")) -> GOIANIA (GO) X BELEM (PA) 07:12
A3: =A2 -> 46101 | B3: ='ESCALA DO FLUXO'!F2 -> 0.3 | D3: ='ESCALA DO FLUXO'!D2 -> 25007 | E3: {=IF(D3="CANCELADO","N/A",_xlfn.XLOOKUP(D3,Tabela6[[#All],[Veículo]],Tabela6[[#All],[Placa]],"N/E",1,1))} -> OGT8A57 | F3: =IFERROR(TRIM(_xlfn.TEXTBEFORE('ESCALA DO FLUXO'!J2,"-")),"CANCELADO") -> CANCELADO | G3: =IFERROR(TRIM(_xlfn.TEXTAFTER('ESCALA DO FLUXO'!J2,"-")),"CANCELADO") -> CANCELADO | H3: =_xlfn.CONCAT('ESCALA DO FLUXO'!K2, " ",TEXT('ESCALA DO FLUXO'!F2,"HH:MM")) -> GOIANIA (GO) X BELEM (PA) 07:12 | J3: CARROS RESERVA | K3: PNEUS RESERVA | L3: OCORRÊNCIAS | M3: OUTROS
A4: =A3 -> 46101 | B4: ='ESCALA DO FLUXO'!F3 -> 0.33333333 | D4: ='ESCALA DO FLUXO'!D3 -> 25011 | E4: {=IF(D4="CANCELADO","N/A",_xlfn.XLOOKUP(D4,Tabela6[[#All],[Veículo]],Tabela6[[#All],[Placa]],"N/E",1,1))} -> OGT8A57 | F4: =IFERROR(TRIM(_xlfn.TEXTBEFORE('ESCALA DO FLUXO'!I3,"-")),"CANCELADO") -> MARCOS ATAIDE SILVA | G4: =IFERROR(TRIM(_xlfn.TEXTAFTER('ESCALA DO FLUXO'!I3,"-")),"CANCELADO") -> 1352 | H4: =_xlfn.CONCAT('ESCALA DO FLUXO'!K3, " ",TEXT('ESCALA DO FLUXO'!F3,"HH:MM")) -> GOIANIA (GO) X SAO LUIS (MA) 08:00 | J4: 16700 | L4: N/A | M4: N/A
A5: =A4 -> 46101 | B5: ='ESCALA DO FLUXO'!F3 -> 0.33333333 | D5: ='ESCALA DO FLUXO'!D3 -> 25011 | E5: {=IF(D5="CANCELADO","N/A",_xlfn.XLOOKUP(D5,Tabela6[[#All],[Veículo]],Tabela6[[#All],[Placa]],"N/E",1,1))} -> OGT8A57 | F5: =IFERROR(TRIM(_xlfn.TEXTBEFORE('ESCALA DO FLUXO'!J3,"-")),"CANCELADO") -> FABIO MOREIRA DOS SANTOS | G5: =IFERROR(TRIM(_xlfn.TEXTAFTER('ESCALA DO FLUXO'!J3,"-")),"CANCELADO") -> 3073 | H5: =_xlfn.CONCAT('ESCALA DO FLUXO'!K3, " ",TEXT('ESCALA DO FLUXO'!F3,"HH:MM")) -> GOIANIA (GO) X SAO LUIS (MA) 08:00 | J5: 15900
A6: =A5 -> 46101 | B6: ='ESCALA DO FLUXO'!F4 -> 0.39583333 | D6: ='ESCALA DO FLUXO'!D4 -> 19005 | E6: {=IF(D6="CANCELADO","N/A",_xlfn.XLOOKUP(D6,Tabela6[[#All],[Veículo]],Tabela6[[#All],[Placa]],"N/E",1,1))} -> QTQ4724 | F6: =IFERROR(TRIM(_xlfn.TEXTBEFORE('ESCALA DO FLUXO'!I4,"-")),"CANCELADO") -> JOSE CARLOS BEZERRA DA SILVA | G6: =IFERROR(TRIM(_xlfn.TEXTAFTER('ESCALA DO FLUXO'!I4,"-")),"CANCELADO") -> 3034 | H6: =_xlfn.CONCAT('ESCALA DO FLUXO'!K4, " ",TEXT('ESCALA DO FLUXO'!F4,"HH:MM")) -> GOIANIA (GO) X TERESINA (PI) VIA STI 09:30
A7: =A6 -> 46101 | B7: ='ESCALA DO FLUXO'!F4 -> 0.39583333 | D7: ='ESCALA DO FLUXO'!D4 -> 19005 | E7: {=IF(D7="CANCELADO","N/A",_xlfn.XLOOKUP(D7,Tabela6[[#All],[Veículo]],Tabela6[[#All],[Placa]],"N/E",1,1))} -> QTQ4724 | F7: =IFERROR(TRIM(_xlfn.TEXTBEFORE('ESCALA DO FLUXO'!J4,"-")),"CANCELADO") -> CANCELADO | G7: =IFERROR(TRIM(_xlfn.TEXTAFTER('ESCALA DO FLUXO'!J4,"-")),"CANCELADO") -> CANCELADO | H7: =_xlfn.CONCAT('ESCALA DO FLUXO'!K4, " ",TEXT('ESCALA DO FLUXO'!F4,"HH:MM")) -> GOIANIA (GO) X TERESINA (PI) VIA STI 09:30
A8: =A7 -> 46101 | B8: ='ESCALA DO FLUXO'!F5 -> 0.41666667 | D8: ='ESCALA DO FLUXO'!D5 -> CANCELADO | E8: {=IF(D8="CANCELADO","N/A",_xlfn.XLOOKUP(D8,Tabela6[[#All],[Veículo]],Tabela6[[#All],[Placa]],"N/E",1,1))} -> N/A | F8: =IFERROR(TRIM(_xlfn.TEXTBEFORE('ESCALA DO FLUXO'!I5,"-")),"CANCELADO") -> CANCELADO | G8: =IFERROR(TRIM(_xlfn.TEXTAFTER('ESCALA DO FLUXO'!I5,"-")),"CANCELADO") -> CANCELADO | H8: =_xlfn.CONCAT('ESCALA DO FLUXO'!K5, " ",TEXT('ESCALA DO FLUXO'!F5,"HH:MM")) -> IMPERATRIZ (MA) X VILA RICA (MT) 10:00
A9: =A8 -> 46101 | B9: =escala_do_fluxo[[#This Row],[HR. RD]] -> 0.41666667 | D9: ='ESCALA DO FLUXO'!D5 -> CANCELADO | E9: {=IF(D9="CANCELADO","N/A",_xlfn.XLOOKUP(D9,Tabela6[[#All],[Veículo]],Tabela6[[#All],[Placa]],"N/E",1,1))} -> N/A | F9: =IFERROR(TRIM(_xlfn.TEXTBEFORE('ESCALA DO FLUXO'!J5,"-")),"CANCELADO") -> CANCELADO | G9: =IFERROR(TRIM(_xlfn.TEXTAFTER('ESCALA DO FLUXO'!J5,"-")),"CANCELADO") -> CANCELADO | H9: =_xlfn.CONCAT('ESCALA DO FLUXO'!K5, " ",TEXT('ESCALA DO FLUXO'!F5,"HH:MM")) -> IMPERATRIZ (MA) X VILA RICA (MT) 10:00
A10: =A9 -> 46101 | B10: ='ESCALA DO FLUXO'!F7 -> 0.38541667 | D10: ='ESCALA DO FLUXO'!D7 -> 19021 | E10: {=IF(D10="CANCELADO","N/A",_xlfn.XLOOKUP(D10,Tabela6[[#All],[Veículo]],Tabela6[[#All],[Placa]],"N/E",1,1))} -> QTR5657 | F10: =IFERROR(TRIM(_xlfn.TEXTBEFORE('ESCALA DO FLUXO'!I7,"-")),"CANCELADO") -> FERNANDO ALVES DE SOUZA | G10: =IFERROR(TRIM(_xlfn.TEXTAFTER('ESCALA DO FLUXO'!I7,"-")),"CANCELADO") -> 6350 | H10: =_xlfn.CONCAT('ESCALA DO FLUXO'!K7, " ",TEXT('ESCALA DO FLUXO'!F7,"HH:MM")) -> GOIANIA (GO) X BELEM (PA) 09:15
A11: =A10 -> 46101 | B11: ='ESCALA DO FLUXO'!F7 -> 0.38541667 | D11: ='ESCALA DO FLUXO'!D7 -> 19021 | E11: {=IF(D11="CANCELADO","N/A",_xlfn.XLOOKUP(D11,Tabela6[[#All],[Veículo]],Tabela6[[#All],[Placa]],"N/E",1,1))} -> QTR5657 | F11: =IFERROR(TRIM(_xlfn.TEXTBEFORE('ESCALA DO FLUXO'!J7,"-")),"CANCELADO") -> AELSON PEREIRA DO NASCIMENTO | G11: =IFERROR(TRIM(_xlfn.TEXTAFTER('ESCALA DO FLUXO'!J7,"-")),"CANCELADO") -> 5682 | H11: =_xlfn.CONCAT('ESCALA DO FLUXO'!K7, " ",TEXT('ESCALA DO FLUXO'!F7,"HH:MM")) -> GOIANIA (GO) X BELEM (PA) 09:15
A12: =A11 -> 46101 | B12: ='ESCALA DO FLUXO'!F6 -> 0.37708333 | D12: ='ESCALA DO FLUXO'!D6 -> 19007 | E12: {=IF(D12="CANCELADO","N/A",_xlfn.XLOOKUP(D12,Tabela6[[#All],[Veículo]],Tabela6[[#All],[Placa]],"N/E",1,1))} -> QTP0317 | F12: =IFERROR(TRIM(_xlfn.TEXTBEFORE('ESCALA DO FLUXO'!I6,"-")),"CANCELADO") -> EDUARDO SANTOS BEZERRA | G12: =IFERROR(TRIM(_xlfn.TEXTAFTER('ESCALA DO FLUXO'!I6,"-")),"CANCELADO") -> 4066 | H12: =_xlfn.CONCAT('ESCALA DO FLUXO'!K6, " ",TEXT('ESCALA DO FLUXO'!F6,"HH:MM")) -> FORTALEZA (CE) X SINOP (MT) 09:03
A13: =A12 -> 46101 | B13: ='ESCALA DO FLUXO'!F16 -> 0.47013889 | D13: ='ESCALA DO FLUXO'!D16 -> 19024 | E13: {=IF(D13="CANCELADO","N/A",_xlfn.XLOOKUP(D13,Tabela6[[#All],[Veículo]],Tabela6[[#All],[Placa]],"N/E",1,1))} -> QTP1769 | F13: =IFERROR(TRIM(_xlfn.TEXTBEFORE('ESCALA DO FLUXO'!I16,"-")),"CANCELADO") -> FRANCISCO BATISTA DE LIMA | G13: =IFERROR(TRIM(_xlfn.TEXTAFTER('ESCALA DO FLUXO'!I16,"-")),"CANCELADO") -> 1827 | H13: =_xlfn.CONCAT('ESCALA DO FLUXO'!K16, " ",TEXT('ESCALA DO FLUXO'!F16,"HH:MM")) -> GOIANIA (GO) X SAO LUIS (MA) 11:17
A14: =A13 -> 46101 | B14: ='ESCALA DO FLUXO'!#REF! -> #REF! | D14: ='ESCALA DO FLUXO'!#REF! -> #REF! | F14: =IFERROR(TRIM(_xlfn.TEXTBEFORE('ESCALA DO FLUXO'!#REF!,"-")),"CANCELADO") -> CANCELADO | G14: =IFERROR(TRIM(_xlfn.TEXTAFTER('ESCALA DO FLUXO'!#REF!,"-")),"CANCELADO") -> CANCELADO | H14: =_xlfn.CONCAT('ESCALA DO FLUXO'!#REF!, " ",TEXT('ESCALA DO FLUXO'!#REF!,"HH:MM")) -> #REF!
A15: =A14 -> 46101 | B15: ='ESCALA DO FLUXO'!#REF! -> #REF! | D15: ='ESCALA DO FLUXO'!#REF! -> #REF! | F15: ='ESCALA DO FLUXO'!#REF! -> #REF! | G15: =IFERROR(TRIM(_xlfn.TEXTAFTER('ESCALA DO FLUXO'!#REF!,"-")),"CANCELADO") -> CANCELADO | H15: =_xlfn.CONCAT('ESCALA DO FLUXO'!#REF!, " ",TEXT('ESCALA DO FLUXO'!#REF!,"HH:MM")) -> #REF!

Sheet FRT NTR BFM
A1: DATA | B1: HORÁRIO | C1: SERVIÇO | D1: FROTA | E1: PLACA | F1: NOME | G1: MAT | H1: LINHA
A2: =escala_do_fluxo[[#This Row],[DATA]] -> 46101 | B2: ='ESCALA DO FLUXO'!F17 -> 0.8125 | D2: ='ESCALA DO FLUXO'!D17 -> 18016 | E2: {=IF(D2="CANCELADO","N/A",_xlfn.XLOOKUP(D2,Tabela6[[#All],[Veículo]],Tabela6[[#All],[Placa]],"N/E",1,1))} -> PRK6658 | F2: =IFERROR(TRIM(_xlfn.TEXTBEFORE('ESCALA DO FLUXO'!I17,"-")),"CANCELADO") -> REGINALDO DE SOUSA OLIVEIRA | G2: =IFERROR(TRIM(_xlfn.TEXTAFTER('ESCALA DO FLUXO'!I17,"-")),"CANCELADO") -> 5412 | H2: =_xlfn.CONCAT('ESCALA DO FLUXO'!K17, " ",TEXT('ESCALA DO FLUXO'!F17,"HH:MM")) -> IMPERATRIZ (MA) X SÃO LUIS (MA) 19:30 | J2: CARROS RESERVA | K2: PNEUS RESERVA | L2: OCORRÊNCIAS | M2: OUTROS
A3: =A2 -> 46101 | B3: ='ESCALA DO FLUXO'!F19 -> 0.79861111 | D3: ='ESCALA DO FLUXO'!D19 -> 19015 | E3: {=IF(D3="CANCELADO","N/A",_xlfn.XLOOKUP(D3,Tabela6[[#All],[Veículo]],Tabela6[[#All],[Placa]],"N/E",1,1))} -> QTS1804 | F3: =IFERROR(TRIM(_xlfn.TEXTBEFORE('ESCALA DO FLUXO'!I19,"-")),"CANCELADO") -> FRANCISCO ALVES DA PAZ JUNIOR | G3: =IFERROR(TRIM(_xlfn.TEXTAFTER('ESCALA DO FLUXO'!I19,"-")),"CANCELADO") -> 1247 | H3: =_xlfn.CONCAT('ESCALA DO FLUXO'!K19, " ",TEXT('ESCALA DO FLUXO'!F19,"HH:MM")) -> GOIANIA (GO) X TERESINA (PI) VIA STI 19:10
A4: =A3 -> 46101 | B4: ='ESCALA DO FLUXO'!F15 -> 0.82777778 | D4: ='ESCALA DO FLUXO'!D15 -> 25012 | E4: {=IF(D4="CANCELADO","N/A",_xlfn.XLOOKUP(D4,Tabela6[[#All],[Veículo]],Tabela6[[#All],[Placa]],"N/E",1,1))} -> OGT8A57 | F4: =IFERROR(TRIM(_xlfn.TEXTBEFORE('ESCALA DO FLUXO'!I15,"-")),"CANCELADO") -> BRUNO MATOS DA ROCHA | G4: =IFERROR(TRIM(_xlfn.TEXTAFTER('ESCALA DO FLUXO'!I15,"-")),"CANCELADO") -> 6013 | H4: =_xlfn.CONCAT('ESCALA DO FLUXO'!K15, " ",TEXT('ESCALA DO FLUXO'!F15,"HH:MM")) -> GOIANIA (GO) X BELEM (PA) 19:52 | J4: 16700 | L4: N/A | M4: N/A
A5: =A4 -> 46101 | B5: ='ESCALA DO FLUXO'!F15 -> 0.82777778 | D5: ='ESCALA DO FLUXO'!D15 -> 25012 | E5: {=IF(D5="CANCELADO","N/A",_xlfn.XLOOKUP(D5,Tabela6[[#All],[Veículo]],Tabela6[[#All],[Placa]],"N/E",1,1))} -> OGT8A57 | F5: =IFERROR(TRIM(_xlfn.TEXTBEFORE('ESCALA DO FLUXO'!J15,"-")),"CANCELADO") -> ANTONIO FRANCINALDO DE OLIVEIRA MARQUES | G5: =IFERROR(TRIM(_xlfn.TEXTAFTER('ESCALA DO FLUXO'!J15,"-")),"CANCELADO") -> 5018 | H5: =_xlfn.CONCAT('ESCALA DO FLUXO'!K15, " ",TEXT('ESCALA DO FLUXO'!F15,"HH:MM")) -> GOIANIA (GO) X BELEM (PA) 19:52 | J5: 15900
A6: =A5 -> 46101 | B6: ='ESCALA DO FLUXO'!F20 -> 0.84166667 | D6: ='ESCALA DO FLUXO'!D20 -> CANCELADO | E6: {=IF(D6="CANCELADO","N/A",_xlfn.XLOOKUP(D6,Tabela6[[#All],[Veículo]],Tabela6[[#All],[Placa]],"N/E",1,1))} -> N/A | F6: =IFERROR(TRIM(_xlfn.TEXTBEFORE('ESCALA DO FLUXO'!I20,"-")),"CANCELADO") -> CANCELADO | G6: =IFERROR(TRIM(_xlfn.TEXTAFTER('ESCALA DO FLUXO'!I20,"-")),"CANCELADO") -> CANCELADO | H6: =_xlfn.CONCAT('ESCALA DO FLUXO'!K20, " ",TEXT('ESCALA DO FLUXO'!F20,"HH:MM")) -> GOIANIA (GO) X SAO LUIS (MA) 20:12
A7: =A6 -> 46101 | B7: ='ESCALA DO FLUXO'!F20 -> 0.84166667 | D7: ='ESCALA DO FLUXO'!D20 -> CANCELADO | E7: {=IF(D7="CANCELADO","N/A",_xlfn.XLOOKUP(D7,Tabela6[[#All],[Veículo]],Tabela6[[#All],[Placa]],"N/E",1,1))} -> N/A | F7: =IFERROR(TRIM(_xlfn.TEXTBEFORE('ESCALA DO FLUXO'!J20,"-")),"CANCELADO") -> CANCELADO | G7: =IFERROR(TRIM(_xlfn.TEXTAFTER('ESCALA DO FLUXO'!J20,"-")),"CANCELADO") -> CANCELADO | H7: =_xlfn.CONCAT('ESCALA DO FLUXO'!K20, " ",TEXT('ESCALA DO FLUXO'!F20,"HH:MM")) -> GOIANIA (GO) X SAO LUIS (MA) 20:12
A8: =A7 -> 46101 | B8: ='ESCALA DO FLUXO'!F18 -> 0.84375 | D8: ='ESCALA DO FLUXO'!D18 -> 25008 | E8: {=IF(D8="CANCELADO","N/A",_xlfn.XLOOKUP(D8,Tabela6[[#All],[Veículo]],Tabela6[[#All],[Placa]],"N/E",1,1))} -> OGT8A57 | F8: =IFERROR(TRIM(_xlfn.TEXTBEFORE('ESCALA DO FLUXO'!I18,"-")),"CANCELADO") -> JARDEL DE SOUSA OLIVEIRA | G8: =IFERROR(TRIM(_xlfn.TEXTAFTER('ESCALA DO FLUXO'!I18,"-")),"CANCELADO") -> 5992 | H8: =_xlfn.CONCAT('ESCALA DO FLUXO'!K18, " ",TEXT('ESCALA DO FLUXO'!F18,"HH:MM")) -> GOIANIA (GO) X SAO LUIS (MA) 20:15
A9: =A8 -> 46101 | B9: ='ESCALA DO FLUXO'!F21 -> 0.85416667 | D9: ='ESCALA DO FLUXO'!D21 -> 19014 | E9: {=IF(D9="CANCELADO","N/A",_xlfn.XLOOKUP(D9,Tabela6[[#All],[Veículo]],Tabela6[[#All],[Placa]],"N/E",1,1))} -> QTS1814 | F9: =IFERROR(TRIM(_xlfn.TEXTBEFORE('ESCALA DO FLUXO'!I21,"-")),"CANCELADO") -> KLEBER OLIVEIRA LIMA | G9: =IFERROR(TRIM(_xlfn.TEXTAFTER('ESCALA DO FLUXO'!I21,"-")),"CANCELADO") -> 5849 | H9: =_xlfn.CONCAT('ESCALA DO FLUXO'!K21, " ",TEXT('ESCALA DO FLUXO'!F21,"HH:MM")) -> FORTALEZA (CE) X SINOP (MT) 20:30
A10: =A9 -> 46101 | B10: ='ESCALA DO FLUXO'!F21 -> 0.85416667 | D10: ='ESCALA DO FLUXO'!D21 -> 19014 | E10: {=IF(D10="CANCELADO","N/A",_xlfn.XLOOKUP(D10,Tabela6[[#All],[Veículo]],Tabela6[[#All],[Placa]],"N/E",1,1))} -> QTS1814 | F10: =IFERROR(TRIM(_xlfn.TEXTBEFORE('ESCALA DO FLUXO'!J21,"-")),"CANCELADO") -> CANCELADO | G10: =IFERROR(TRIM(_xlfn.TEXTAFTER('ESCALA DO FLUXO'!J21,"-")),"CANCELADO") -> CANCELADO | H10: =_xlfn.CONCAT('ESCALA DO FLUXO'!K21, " ",TEXT('ESCALA DO FLUXO'!F21,"HH:MM")) -> FORTALEZA (CE) X SINOP (MT) 20:30
A11: =A10 -> 46101 | B11: ='ESCALA DO FLUXO'!F22 -> 0.87847222 | D11: ='ESCALA DO FLUXO'!D22 -> 19010 | E11: {=IF(D11="CANCELADO","N/A",_xlfn.XLOOKUP(D11,Tabela6[[#All],[Veículo]],Tabela6[[#All],[Placa]],"N/E",1,1))} -> QTO8077 | F11: =IFERROR(TRIM(_xlfn.TEXTBEFORE('ESCALA DO FLUXO'!I22,"-")),"CANCELADO") -> MARCIO DE SOUSA MATOS | G11: =IFERROR(TRIM(_xlfn.TEXTAFTER('ESCALA DO FLUXO'!I22,"-")),"CANCELADO") -> 5264 | H11: =_xlfn.CONCAT('ESCALA DO FLUXO'!K22, " ",TEXT('ESCALA DO FLUXO'!F22,"HH:MM")) -> GOIANIA (GO) X BELEM (PA) 21:05
A12: =A11 -> 46101 | B12: ='ESCALA DO FLUXO'!F22 -> 0.87847222 | D12: ='ESCALA DO FLUXO'!D22 -> 19010 | E12: {=IF(D12="CANCELADO","N/A",_xlfn.XLOOKUP(D12,Tabela6[[#All],[Veículo]],Tabela6[[#All],[Placa]],"N/E",1,1))} -> QTO8077 | F12: =IFERROR(TRIM(_xlfn.TEXTBEFORE('ESCALA DO FLUXO'!J22,"-")),"CANCELADO") -> ANDSON WAGNER NASCIMENTO SOUZA | G12: =IFERROR(TRIM(_xlfn.TEXTAFTER('ESCALA DO FLUXO'!J22,"-")),"CANCELADO") -> 2902 | H12: =_xlfn.CONCAT('ESCALA DO FLUXO'!K22, " ",TEXT('ESCALA DO FLUXO'!F22,"HH:MM")) -> GOIANIA (GO) X BELEM (PA) 21:05
A13: =A12 -> 46101 | B13: ='ESCALA DO FLUXO'!F23 -> 0 | D13: ='ESCALA DO FLUXO'!D23 -> 0 | E13: {=IF(D13="CANCELADO","N/A",_xlfn.XLOOKUP(D13,Tabela6[[#All],[Veículo]],Tabela6[[#All],[Placa]],"N/E",1,1))} -> SPE0F17 | F13: =IFERROR(TRIM(_xlfn.TEXTBEFORE('ESCALA DO FLUXO'!I23,"-")),"CANCELADO") -> CANCELADO | G13: =IFERROR(TRIM(_xlfn.TEXTAFTER('ESCALA DO FLUXO'!J23,"-")),"CANCELADO") -> CANCELADO | H13: TERESINA X GOIANIA 20:35 EXTRA
A14: =A13 -> 46101 | B14: 0.85763889 | D14: 17000 | E14: PQZ3I84 | F14: =IFERROR(TRIM(_xlfn.TEXTBEFORE('ESCALA DO FLUXO'!J23,"-")),"CANCELADO") -> CANCELADO | G14: =IFERROR(TRIM(_xlfn.TEXTAFTER('ESCALA DO FLUXO'!J24,"-")),"CANCELADO") -> CANCELADO | H14: TERESINA X GOIANIA 20:35 EXTRA

Sheet CONSULTA DE PLACA
B5: DIGITE A PLACA | C5: RESULTADO (CARRO): | E5: DIGITE O CARRO | F5: RESULTADO (PLACA):
C6: =_xlfn.XLOOKUP(B6,Tabela6[Placa],Tabela6[Veículo],"N/E",1,1) -> N/E | F6: =_xlfn.XLOOKUP(E6,Tabela6[Veículo],Tabela6[Placa],"N/E",1,1) -> N/E

Sheet BANCO DE DADOS
A1: MOTORISTA | B1: MATRICULA | C1: MOTORISTA + MATRICULA | E1: Veículo | F1: Placa
A2: VALDIR PEREIRA DE SOUZA | B2: 85 | C2: VALDIR PEREIRA DE SOUZA - 85 | E2: GOL | F2: NVO2044 | I2: BACK-END INFO
A3: WILSON MARTINS ROCHA | B3: 105 | C3: WILSON MARTINS ROCHA - 105 | E3: 11800 | F3: OMR4C73 | I3: 0.57291667
A4: CLAUDIO JOSE DO NASCIMENTO | B4: 549 | C4: CLAUDIO JOSE DO NASCIMENTO - 549 | E4: 11900 | F4: ONA8083
A5: PEDRO ALVES DE OLIVEIRA | B5: 556 | C5: PEDRO ALVES DE OLIVEIRA - 556 | E5: 12000 | F5: OMX2213 | I5: =TEXT(NOW(),"DD/MM/AA") -> 20/03/26
A6: ELISEU TORRES DE OLIVEIRA | B6: 561 | C6: ELISEU TORRES DE OLIVEIRA - 561 | E6: 12200 | F6: OMX2193
A7: ROMILDO ALVES DE CARVALHO | B7: 568 | C7: ROMILDO ALVES DE CARVALHO - 568 | E7: 12400 | F7: OOE4685 | I7: =IF(TEXT(I5,"DD")/2=0,"GABRIEL","GUSTAVO") -> GUSTAVO
A8: EVANDRO CARLOS ARAUJO LIMA | B8: 569 | C8: EVANDRO CARLOS ARAUJO LIMA - 569 | E8: RANGER | F8: OGJ7J55
A9: GESMAR DE SOUZA | B9: 574 | C9: GESMAR DE SOUZA - 574 | E9: 13000 | F9: ONZ2254
A10: VALDEVANDE BENTO DE OLIVEIRA | B10: 728 | C10: VALDEVANDE BENTO DE OLIVEIRA - 728 | E10: 13700 | F10: ONH3001
A11: FRANCISCO RODRIGUES DE SOUSA | B11: 735 | C11: FRANCISCO RODRIGUES DE SOUSA - 735 | E11: 14000 | F11: OMK0001 | I11: =IF(I3<"12:00","MANHÃ","TARDE") -> MANHÃ
A12: GONCALO ALVES BEZERRA | B12: 748 | C12: GONCALO ALVES BEZERRA - 748 | E12: 14010 | F12: AZB9B04
A13: HILTON RODRIGUES DA COSTA | B13: 866 | C13: HILTON RODRIGUES DA COSTA - 866 | E13: 14200 | F13: ONI0A01 | I13: =IF(PAINEL!H15="","",(IF(_xlfn.XLOOKUP(PAINEL!H15,PAINEL!#REF!,PAINEL!#REF!,"CARRO NÃO ENCONTRADO")="DISPONÍVEL","ESSE CARRO ESTÁ DISPONÍVEL","(ESCREVER OBSERVAÇÃO)")))
A14: MAURICIO CARLOS BARROSO | B14: 901 | C14: MAURICIO CARLOS BARROSO - 901 | E14: 14300 | F14: OMO3002
A15: EDIVALDO DOS SANTOS SOUZA | B15: 905 | C15: EDIVALDO DOS SANTOS SOUZA - 905 | E15: 14400 | F15: ONJ1472
A16: GERALDO MAGELA DA COSTA | B16: 906 | C16: GERALDO MAGELA DA COSTA - 906 | E16: 14500 | F16: ONF6622
A17: RAIMUNDO FERNANDES RIBEIRO | B17: 907 | C17: RAIMUNDO FERNANDES RIBEIRO - 907 | E17: 14700 | F17: ONJ1222
A18: ARTMAN DA COSTA ROCHA | B18: 920 | C18: ARTMAN DA COSTA ROCHA - 920 | E18: 14800 | F18: ONQ6F39
A19: JAMES RIBEIRO TAVARES | B19: 939 | C19: JAMES RIBEIRO TAVARES - 939 | E19: 15200 | F19: OOC4I69
A20: VILMAR JOSE CAMILO | B20: 948 | C20: VILMAR JOSE CAMILO - 948 | E20: 15300 | F20: OOC4069
A21: IZALMIR RODRIGUES COELHO | B21: 958 | C21: IZALMIR RODRIGUES COELHO - 958 | E21: 15400 | F21: ONQ6409
A22: JOSE CARLOS DA SILVA | B22: 979 | C22: JOSE CARLOS DA SILVA - 979 | E22: 15500 | F22: PQA3683
A23: ZELIO ALVES DUARTE | B23: 990 | C23: ZELIO ALVES DUARTE - 990 | E23: 15600 | F23: OOC4709
A24: SEBASTIAO ROSA DA SILVA | B24: 1006 | C24: SEBASTIAO ROSA DA SILVA - 1006 | E24: 15700 | F24: OOC4529
A25: CLOVIS MARQUES | B25: 1065 | C25: CLOVIS MARQUES - 1065 | E25: 15800 | F25: PQS4686
... A138: VALDIVINO VIEIRA DE OLIVEIRA | B138: 2446 | C138: VALDIVINO VIEIRA DE OLIVEIRA - 2446 | E138: 24020 | F138: SCU3F69
A139: WESLEI PEREIRA DE MOURA | B139: 2449 | C139: WESLEI PEREIRA DE MOURA - 2449 | E139: 24021 | F139: 24021
A140: URCELY MARCAL ARAUJO | B140: 2450 | C140: URCELY MARCAL ARAUJO - 2450 | E140: 24022 | F140: SDH1J19
A141: SERGIO FERNANDO DE MOURA | B141: 2455 | C141: SERGIO FERNANDO DE MOURA - 2455 | E141: 24023 | F141: 24023
A142: ZAILON DANTAS DA SILVA | B142: 2459 | C142: ZAILON DANTAS DA SILVA - 2459 | E142: 241601 | F142: PPQ3E66
A143: SILVANIO NOGUEIRA DE SOUSA | B143: 2493 | C143: SILVANIO NOGUEIRA DE SOUSA - 2493 | E143: 241801 | F143: QOR4938
A144: SIRLON DE OLIVEIRA BRITO | B144: 2497 | C144: SIRLON DE OLIVEIRA BRITO - 2497 | E144: 2620 | F144: SPC9D25
A145: THIAGO JOSE TEIXEIRA | B145: 2502 | C145: THIAGO JOSE TEIXEIRA - 2502 | E145: 2630 | F145: SPC9D35
A146: WESLEY DE PAULA ALBERNAZ | B146: 2504 | C146: WESLEY DE PAULA ALBERNAZ - 2504 | E146: 28 - S10 GYN | F146: PQX3D14
A147: VALTAIR PEREIRA TAVARES | B147: 2510 | C147: VALTAIR PEREIRA TAVARES - 2510 | E147: 31 - STRADA CBA | F147: NKZ8B87
A148: LUIZ ODETE BATISTA FLOZ | B148: 2511 | C148: LUIZ ODETE BATISTA FLOZ - 2511 | E148: AG 2342 | F148: RRX1E53
A149: VALDEONE CLEMENTE DOS SANTOS | B149: 2513 | C149: VALDEONE CLEMENTE DOS SANTOS - 2513 | E149: AG-65 | F149: PRP6E96
A150: VALDINEY DA SILVA SANTOS | B150: 2530 | C150: VALDINEY DA SILVA SANTOS - 2530 | E150: AG-66 | F150: PRP6D56
A151: RONALDO MANOEL TEIXEIRA | B151: 2541 | C151: RONALDO MANOEL TEIXEIRA - 2541 | E151: AG-67 | F151: AG67
A152: IDEIR BISPO DE SANTANA | B152: 2543 | C152: IDEIR BISPO DE SANTANA - 2543 | E152: Automatico [915601] | F152: 915601
...
